
Error Date/Time:2023-10-25 12:08:30
URL:http://localhost:8000/appointments/api/create-patient/
Error:TypeError("save_analytics() missing 1 required positional argument: 'request'")
\Traceback (most recent call last):
  File "/home/atifusman/Projects/patients_counsellor_appointments/patients_counsellor_appointments/appointmentsapp/views.py", line 51, in post
    analytics=save_analytics(action,request)
TypeError: save_analytics() missing 1 required positional argument: 'request'

Cuurent Inputs:{}
Error Date/Time:2023-10-25 12:32:50
URL:http://localhost:8000/appointments/api/create-patient/
Error:AssertionError("The field 'patient_code' was declared on serializer PatientSerializer, but has not been included in the 'fields' option.")
\Traceback (most recent call last):
  File "/home/atifusman/Projects/patients_counsellor_appointments/patients_counsellor_appointments/appointmentsapp/views.py", line 60, in post
    if serializer.is_valid():
  File "/home/atifusman/Projects/patients_counsellor_appointments/.venv/lib/python3.9/site-packages/rest_framework/serializers.py", line 220, in is_valid
    self._validated_data = self.run_validation(self.initial_data)
  File "/home/atifusman/Projects/patients_counsellor_appointments/.venv/lib/python3.9/site-packages/rest_framework/serializers.py", line 419, in run_validation
    value = self.to_internal_value(data)
  File "/home/atifusman/Projects/patients_counsellor_appointments/.venv/lib/python3.9/site-packages/rest_framework/serializers.py", line 472, in to_internal_value
    for field in fields:
  File "/home/atifusman/Projects/patients_counsellor_appointments/.venv/lib/python3.9/site-packages/rest_framework/serializers.py", line 355, in _writable_fields
    for field in self.fields.values():
  File "/home/atifusman/Projects/patients_counsellor_appointments/.venv/lib/python3.9/site-packages/django/utils/functional.py", line 48, in __get__
    res = instance.__dict__[self.name] = self.func(instance)
  File "/home/atifusman/Projects/patients_counsellor_appointments/.venv/lib/python3.9/site-packages/rest_framework/serializers.py", line 349, in fields
    for key, value in self.get_fields().items():
  File "/home/atifusman/Projects/patients_counsellor_appointments/.venv/lib/python3.9/site-packages/rest_framework/serializers.py", line 1029, in get_fields
    field_names = self.get_field_names(declared_fields, info)
  File "/home/atifusman/Projects/patients_counsellor_appointments/.venv/lib/python3.9/site-packages/rest_framework/serializers.py", line 1125, in get_field_names
    assert field_name in fields, (
AssertionError: The field 'patient_code' was declared on serializer PatientSerializer, but has not been included in the 'fields' option.

Cuurent Inputs:{}
Error Date/Time:2023-10-25 12:33:49
URL:http://localhost:8000/appointments/api/create-patient/
Error:AssertionError("The field 'patient_code' was declared on serializer PatientSerializer, but has not been included in the 'fields' option.")
\Traceback (most recent call last):
  File "/home/atifusman/Projects/patients_counsellor_appointments/patients_counsellor_appointments/appointmentsapp/views.py", line 60, in post
    if serializer.is_valid():
  File "/home/atifusman/Projects/patients_counsellor_appointments/.venv/lib/python3.9/site-packages/rest_framework/serializers.py", line 220, in is_valid
    self._validated_data = self.run_validation(self.initial_data)
  File "/home/atifusman/Projects/patients_counsellor_appointments/.venv/lib/python3.9/site-packages/rest_framework/serializers.py", line 419, in run_validation
    value = self.to_internal_value(data)
  File "/home/atifusman/Projects/patients_counsellor_appointments/.venv/lib/python3.9/site-packages/rest_framework/serializers.py", line 472, in to_internal_value
    for field in fields:
  File "/home/atifusman/Projects/patients_counsellor_appointments/.venv/lib/python3.9/site-packages/rest_framework/serializers.py", line 355, in _writable_fields
    for field in self.fields.values():
  File "/home/atifusman/Projects/patients_counsellor_appointments/.venv/lib/python3.9/site-packages/django/utils/functional.py", line 48, in __get__
    res = instance.__dict__[self.name] = self.func(instance)
  File "/home/atifusman/Projects/patients_counsellor_appointments/.venv/lib/python3.9/site-packages/rest_framework/serializers.py", line 349, in fields
    for key, value in self.get_fields().items():
  File "/home/atifusman/Projects/patients_counsellor_appointments/.venv/lib/python3.9/site-packages/rest_framework/serializers.py", line 1029, in get_fields
    field_names = self.get_field_names(declared_fields, info)
  File "/home/atifusman/Projects/patients_counsellor_appointments/.venv/lib/python3.9/site-packages/rest_framework/serializers.py", line 1125, in get_field_names
    assert field_name in fields, (
AssertionError: The field 'patient_code' was declared on serializer PatientSerializer, but has not been included in the 'fields' option.

Cuurent Inputs:{}
Error Date/Time:2023-10-25 12:35:54
URL:http://localhost:8000/appointments/api/create-patient/
Error:IntegrityError(1048, "Column 'deleted_date' cannot be null")
\Traceback (most recent call last):
  File "/home/atifusman/Projects/patients_counsellor_appointments/.venv/lib/python3.9/site-packages/django/db/backends/mysql/base.py", line 73, in execute
    return self.cursor.execute(query, args)
  File "/home/atifusman/Projects/patients_counsellor_appointments/.venv/lib/python3.9/site-packages/MySQLdb/cursors.py", line 206, in execute
    res = self._query(query)
  File "/home/atifusman/Projects/patients_counsellor_appointments/.venv/lib/python3.9/site-packages/MySQLdb/cursors.py", line 319, in _query
    db.query(q)
  File "/home/atifusman/Projects/patients_counsellor_appointments/.venv/lib/python3.9/site-packages/MySQLdb/connections.py", line 259, in query
    _mysql.connection.query(self, query)
MySQLdb._exceptions.OperationalError: (1048, "Column 'deleted_date' cannot be null")

During handling of the above exception, another exception occurred:

Traceback (most recent call last):
  File "/home/atifusman/Projects/patients_counsellor_appointments/patients_counsellor_appointments/appointmentsapp/views.py", line 61, in post
    patient= serializer.save()
  File "/home/atifusman/Projects/patients_counsellor_appointments/.venv/lib/python3.9/site-packages/rest_framework/serializers.py", line 205, in save
    self.instance = self.create(validated_data)
  File "/home/atifusman/Projects/patients_counsellor_appointments/.venv/lib/python3.9/site-packages/rest_framework/serializers.py", line 939, in create
    instance = ModelClass._default_manager.create(**validated_data)
  File "/home/atifusman/Projects/patients_counsellor_appointments/.venv/lib/python3.9/site-packages/django/db/models/manager.py", line 85, in manager_method
    return getattr(self.get_queryset(), name)(*args, **kwargs)
  File "/home/atifusman/Projects/patients_counsellor_appointments/.venv/lib/python3.9/site-packages/django/db/models/query.py", line 453, in create
    obj.save(force_insert=True, using=self.db)
  File "/home/atifusman/Projects/patients_counsellor_appointments/.venv/lib/python3.9/site-packages/django/db/models/base.py", line 726, in save
    self.save_base(using=using, force_insert=force_insert,
  File "/home/atifusman/Projects/patients_counsellor_appointments/.venv/lib/python3.9/site-packages/django/db/models/base.py", line 763, in save_base
    updated = self._save_table(
  File "/home/atifusman/Projects/patients_counsellor_appointments/.venv/lib/python3.9/site-packages/django/db/models/base.py", line 868, in _save_table
    results = self._do_insert(cls._base_manager, using, fields, returning_fields, raw)
  File "/home/atifusman/Projects/patients_counsellor_appointments/.venv/lib/python3.9/site-packages/django/db/models/base.py", line 906, in _do_insert
    return manager._insert(
  File "/home/atifusman/Projects/patients_counsellor_appointments/.venv/lib/python3.9/site-packages/django/db/models/manager.py", line 85, in manager_method
    return getattr(self.get_queryset(), name)(*args, **kwargs)
  File "/home/atifusman/Projects/patients_counsellor_appointments/.venv/lib/python3.9/site-packages/django/db/models/query.py", line 1270, in _insert
    return query.get_compiler(using=using).execute_sql(returning_fields)
  File "/home/atifusman/Projects/patients_counsellor_appointments/.venv/lib/python3.9/site-packages/django/db/models/sql/compiler.py", line 1416, in execute_sql
    cursor.execute(sql, params)
  File "/home/atifusman/Projects/patients_counsellor_appointments/.venv/lib/python3.9/site-packages/django/db/backends/utils.py", line 98, in execute
    return super().execute(sql, params)
  File "/home/atifusman/Projects/patients_counsellor_appointments/.venv/lib/python3.9/site-packages/django/db/backends/utils.py", line 66, in execute
    return self._execute_with_wrappers(sql, params, many=False, executor=self._execute)
  File "/home/atifusman/Projects/patients_counsellor_appointments/.venv/lib/python3.9/site-packages/django/db/backends/utils.py", line 75, in _execute_with_wrappers
    return executor(sql, params, many, context)
  File "/home/atifusman/Projects/patients_counsellor_appointments/.venv/lib/python3.9/site-packages/django/db/backends/utils.py", line 84, in _execute
    return self.cursor.execute(sql, params)
  File "/home/atifusman/Projects/patients_counsellor_appointments/.venv/lib/python3.9/site-packages/django/db/backends/mysql/base.py", line 78, in execute
    raise IntegrityError(*tuple(e.args))
django.db.utils.IntegrityError: (1048, "Column 'deleted_date' cannot be null")

Cuurent Inputs:<QueryDict: {'patient_name': ['Atif fUsman'], 'patient_email': ['atifusman@test.com'], 'patient_password': ['test@123']}>
Error Date/Time:2023-10-25 14:06:28
URL:http://localhost:8000/appointments/api/patient-list/
Error:NameError("name 'Patient' is not defined")
\Traceback (most recent call last):
  File "/home/atifusman/Projects/patients_counsellor_appointments/patients_counsellor_appointments/appointmentsapp/views.py", line 101, in get
    queryset=Patient.objects.filter(is_active=True).order_by('-patient_id')
NameError: name 'Patient' is not defined

Cuurent Inputs:{}
Error Date/Time:2023-10-25 14:07:31
URL:http://localhost:8000/appointments/api/patient-list/
Error:NameError("name 'math' is not defined")
\Traceback (most recent call last):
  File "/home/atifusman/Projects/patients_counsellor_appointments/patients_counsellor_appointments/appointmentsapp/views.py", line 112, in get
    total_pages=int(math.ceil(total_records/reqRecs))
NameError: name 'math' is not defined

Cuurent Inputs:{}
Error Date/Time:2023-10-25 14:17:23
URL:http://localhost:8000/appointments/api/counsellor-list/
Error:FieldError("Cannot resolve keyword 'patient_id' into field. Choices are: appointment, counsellor_code, counsellor_email, counsellor_id, counsellor_name, counsellor_password, create_date, deleted_date, is_active, modified_date")
\Traceback (most recent call last):
  File "/home/atifusman/Projects/patients_counsellor_appointments/patients_counsellor_appointments/appointmentsapp/views.py", line 197, in get
    queryset=Counsellor.objects.filter(is_active=True).order_by('-patient_id')
  File "/home/atifusman/Projects/patients_counsellor_appointments/.venv/lib/python3.9/site-packages/django/db/models/query.py", line 1149, in order_by
    obj.query.add_ordering(*field_names)
  File "/home/atifusman/Projects/patients_counsellor_appointments/.venv/lib/python3.9/site-packages/django/db/models/sql/query.py", line 1993, in add_ordering
    self.names_to_path(item.split(LOOKUP_SEP), self.model._meta)
  File "/home/atifusman/Projects/patients_counsellor_appointments/.venv/lib/python3.9/site-packages/django/db/models/sql/query.py", line 1539, in names_to_path
    raise FieldError("Cannot resolve keyword '%s' into field. "
django.core.exceptions.FieldError: Cannot resolve keyword 'patient_id' into field. Choices are: appointment, counsellor_code, counsellor_email, counsellor_id, counsellor_name, counsellor_password, create_date, deleted_date, is_active, modified_date

Cuurent Inputs:<QueryDict: {'page': ['1'], 'reqRecs': ['10']}>
Error Date/Time:2023-10-25 14:18:38
URL:http://localhost:8000/appointments/api/counsellor-list/
Error:KeyError('patient_password')
\Traceback (most recent call last):
  File "/home/atifusman/Projects/patients_counsellor_appointments/patients_counsellor_appointments/appointmentsapp/views.py", line 214, in get
    val.pop('patient_password')
KeyError: 'patient_password'

Cuurent Inputs:<QueryDict: {'page': ['1'], 'reqRecs': ['10']}>
Error Date/Time:2023-10-25 15:05:36
URL:http://localhost:8000/appointments/api/patient-delete/
Error:AttributeError("'str' object has no attribute 'deleted_date'")
\Traceback (most recent call last):
  File "/home/atifusman/Projects/patients_counsellor_appointments/patients_counsellor_appointments/appointmentsapp/views.py", line 105, in post
    patient_id.deleted_date=datetime.datetime.now
AttributeError: 'str' object has no attribute 'deleted_date'

Cuurent Inputs:<QueryDict: {'patient_id': ['1']}>
Error Date/Time:2023-10-25 15:06:20
URL:http://localhost:8000/appointments/api/patient-delete/
Error:AttributeError("'str' object has no attribute 'deleted_date'")
\Traceback (most recent call last):
  File "/home/atifusman/Projects/patients_counsellor_appointments/patients_counsellor_appointments/appointmentsapp/views.py", line 105, in post
    patient_id.deleted_date=current_date_time()
AttributeError: 'str' object has no attribute 'deleted_date'

Cuurent Inputs:<QueryDict: {'patient_id': ['1']}>
Error Date/Time:2023-10-25 15:45:54
URL:http://localhost:8000/appointments/api/patient-update/
Error:NameError("name 'required_data' is not defined")
\Traceback (most recent call last):
  File "/home/atifusman/Projects/patients_counsellor_appointments/patients_counsellor_appointments/appointmentsapp/views.py", line 194, in post
    response={'msg':'fail','status':400,'data':required_data,'errors':str(serializer.errors)}
NameError: name 'required_data' is not defined

Cuurent Inputs:<QueryDict: {'patient_id': ['1'], 'patient_name': ['Atif Usman Hashim Hajo Ahmed']}>
Error Date/Time:2023-10-25 16:34:41
URL:http://localhost:8000/appointments/api/create-patient-appointment/
Error:AssertionError("The field 'appointment_date_time' was declared on serializer AppointmentSerializer, but has not been included in the 'fields' option.")
\Traceback (most recent call last):
  File "/home/atifusman/Projects/patients_counsellor_appointments/patients_counsellor_appointments/appointmentsapp/views.py", line 536, in post
    if serializer.is_valid():
  File "/home/atifusman/Projects/patients_counsellor_appointments/.venv/lib/python3.9/site-packages/rest_framework/serializers.py", line 220, in is_valid
    self._validated_data = self.run_validation(self.initial_data)
  File "/home/atifusman/Projects/patients_counsellor_appointments/.venv/lib/python3.9/site-packages/rest_framework/serializers.py", line 419, in run_validation
    value = self.to_internal_value(data)
  File "/home/atifusman/Projects/patients_counsellor_appointments/.venv/lib/python3.9/site-packages/rest_framework/serializers.py", line 472, in to_internal_value
    for field in fields:
  File "/home/atifusman/Projects/patients_counsellor_appointments/.venv/lib/python3.9/site-packages/rest_framework/serializers.py", line 355, in _writable_fields
    for field in self.fields.values():
  File "/home/atifusman/Projects/patients_counsellor_appointments/.venv/lib/python3.9/site-packages/django/utils/functional.py", line 48, in __get__
    res = instance.__dict__[self.name] = self.func(instance)
  File "/home/atifusman/Projects/patients_counsellor_appointments/.venv/lib/python3.9/site-packages/rest_framework/serializers.py", line 349, in fields
    for key, value in self.get_fields().items():
  File "/home/atifusman/Projects/patients_counsellor_appointments/.venv/lib/python3.9/site-packages/rest_framework/serializers.py", line 1029, in get_fields
    field_names = self.get_field_names(declared_fields, info)
  File "/home/atifusman/Projects/patients_counsellor_appointments/.venv/lib/python3.9/site-packages/rest_framework/serializers.py", line 1125, in get_field_names
    assert field_name in fields, (
AssertionError: The field 'appointment_date_time' was declared on serializer AppointmentSerializer, but has not been included in the 'fields' option.

Cuurent Inputs:<QueryDict: {'patient_id': ['1'], 'appointment_date': ['2023-11-29']}>
Error Date/Time:2023-10-25 16:36:27
URL:http://localhost:8000/appointments/api/create-patient-appointment/
Error:AssertionError("It is redundant to specify `source='appointment_date'` on field 'DateTimeField' in serializer 'AppointmentSerializer', because it is the same as the field name. Remove the `source` keyword argument.")
\Traceback (most recent call last):
  File "/home/atifusman/Projects/patients_counsellor_appointments/patients_counsellor_appointments/appointmentsapp/views.py", line 536, in post
    if serializer.is_valid():
  File "/home/atifusman/Projects/patients_counsellor_appointments/.venv/lib/python3.9/site-packages/rest_framework/serializers.py", line 220, in is_valid
    self._validated_data = self.run_validation(self.initial_data)
  File "/home/atifusman/Projects/patients_counsellor_appointments/.venv/lib/python3.9/site-packages/rest_framework/serializers.py", line 419, in run_validation
    value = self.to_internal_value(data)
  File "/home/atifusman/Projects/patients_counsellor_appointments/.venv/lib/python3.9/site-packages/rest_framework/serializers.py", line 472, in to_internal_value
    for field in fields:
  File "/home/atifusman/Projects/patients_counsellor_appointments/.venv/lib/python3.9/site-packages/rest_framework/serializers.py", line 355, in _writable_fields
    for field in self.fields.values():
  File "/home/atifusman/Projects/patients_counsellor_appointments/.venv/lib/python3.9/site-packages/django/utils/functional.py", line 48, in __get__
    res = instance.__dict__[self.name] = self.func(instance)
  File "/home/atifusman/Projects/patients_counsellor_appointments/.venv/lib/python3.9/site-packages/rest_framework/serializers.py", line 350, in fields
    fields[key] = value
  File "/home/atifusman/Projects/patients_counsellor_appointments/.venv/lib/python3.9/site-packages/rest_framework/utils/serializer_helpers.py", line 152, in __setitem__
    field.bind(field_name=key, parent=self.serializer)
  File "/home/atifusman/Projects/patients_counsellor_appointments/.venv/lib/python3.9/site-packages/rest_framework/fields.py", line 378, in bind
    assert self.source != field_name, (
AssertionError: It is redundant to specify `source='appointment_date'` on field 'DateTimeField' in serializer 'AppointmentSerializer', because it is the same as the field name. Remove the `source` keyword argument.

Cuurent Inputs:<QueryDict: {'patient_id': ['1'], 'appointment_date': ['2023-11-29']}>
Error Date/Time:2023-10-25 16:38:09
URL:http://localhost:8000/appointments/api/create-patient-appointment/
Error:AssertionError("It is redundant to specify `source='appointment_date'` on field 'DateField' in serializer 'AppointmentSerializer', because it is the same as the field name. Remove the `source` keyword argument.")
\Traceback (most recent call last):
  File "/home/atifusman/Projects/patients_counsellor_appointments/patients_counsellor_appointments/appointmentsapp/views.py", line 536, in post
    if serializer.is_valid():
  File "/home/atifusman/Projects/patients_counsellor_appointments/.venv/lib/python3.9/site-packages/rest_framework/serializers.py", line 220, in is_valid
    self._validated_data = self.run_validation(self.initial_data)
  File "/home/atifusman/Projects/patients_counsellor_appointments/.venv/lib/python3.9/site-packages/rest_framework/serializers.py", line 419, in run_validation
    value = self.to_internal_value(data)
  File "/home/atifusman/Projects/patients_counsellor_appointments/.venv/lib/python3.9/site-packages/rest_framework/serializers.py", line 472, in to_internal_value
    for field in fields:
  File "/home/atifusman/Projects/patients_counsellor_appointments/.venv/lib/python3.9/site-packages/rest_framework/serializers.py", line 355, in _writable_fields
    for field in self.fields.values():
  File "/home/atifusman/Projects/patients_counsellor_appointments/.venv/lib/python3.9/site-packages/django/utils/functional.py", line 48, in __get__
    res = instance.__dict__[self.name] = self.func(instance)
  File "/home/atifusman/Projects/patients_counsellor_appointments/.venv/lib/python3.9/site-packages/rest_framework/serializers.py", line 350, in fields
    fields[key] = value
  File "/home/atifusman/Projects/patients_counsellor_appointments/.venv/lib/python3.9/site-packages/rest_framework/utils/serializer_helpers.py", line 152, in __setitem__
    field.bind(field_name=key, parent=self.serializer)
  File "/home/atifusman/Projects/patients_counsellor_appointments/.venv/lib/python3.9/site-packages/rest_framework/fields.py", line 378, in bind
    assert self.source != field_name, (
AssertionError: It is redundant to specify `source='appointment_date'` on field 'DateField' in serializer 'AppointmentSerializer', because it is the same as the field name. Remove the `source` keyword argument.

Cuurent Inputs:<QueryDict: {'patient_id': ['1'], 'appointment_date': ['2023-11-29']}>
Error Date/Time:2023-10-25 17:20:04
URL:http://localhost:8000/appointments/api/create-appointment/
Error:NameError("name 'appointment_date' is not defined")
\Traceback (most recent call last):
  File "/home/atifusman/Projects/patients_counsellor_appointments/patients_counsellor_appointments/appointmentsapp/views.py", line 515, in post
    'appointment_date':appointment_date
NameError: name 'appointment_date' is not defined

Cuurent Inputs:<QueryDict: {'patient_id': ['1'], 'appointment_date': ['2023-11-29'], 'counseller_id': ['2']}>
Error Date/Time:2023-10-25 17:37:53
URL:http://localhost:8000/appointments/api/active-appointment-list/
Error:AssertionError('Expected a `date`, but got a `datetime`. Refusing to coerce, as this may mean losing timezone information. Use a custom read-only field and deal with timezone issues explicitly.')
\Traceback (most recent call last):
  File "/home/atifusman/Projects/patients_counsellor_appointments/patients_counsellor_appointments/appointmentsapp/views.py", line 575, in get
    response={'msg':'success','status':200,'total_pages':total_pages,'total_records':total_records,'current_page':page,'records':data_list.count(),'data':serializer.data}
  File "/home/atifusman/Projects/patients_counsellor_appointments/.venv/lib/python3.9/site-packages/rest_framework/serializers.py", line 745, in data
    ret = super().data
  File "/home/atifusman/Projects/patients_counsellor_appointments/.venv/lib/python3.9/site-packages/rest_framework/serializers.py", line 246, in data
    self._data = self.to_representation(self.instance)
  File "/home/atifusman/Projects/patients_counsellor_appointments/.venv/lib/python3.9/site-packages/rest_framework/serializers.py", line 663, in to_representation
    return [
  File "/home/atifusman/Projects/patients_counsellor_appointments/.venv/lib/python3.9/site-packages/rest_framework/serializers.py", line 664, in <listcomp>
    self.child.to_representation(item) for item in iterable
  File "/home/atifusman/Projects/patients_counsellor_appointments/.venv/lib/python3.9/site-packages/rest_framework/serializers.py", line 515, in to_representation
    ret[field.field_name] = field.to_representation(attribute)
  File "/home/atifusman/Projects/patients_counsellor_appointments/.venv/lib/python3.9/site-packages/rest_framework/fields.py", line 1298, in to_representation
    assert not isinstance(value, datetime.datetime), (
AssertionError: Expected a `date`, but got a `datetime`. Refusing to coerce, as this may mean losing timezone information. Use a custom read-only field and deal with timezone issues explicitly.

Cuurent Inputs:<QueryDict: {'patient_id': ['1'], 'appointment_date': ['2023-11-29']}>
Error Date/Time:2023-10-25 17:42:24
URL:http://localhost:8000/appointments/api/active-appointment-list/
Error:AssertionError("It is redundant to specify `source='appointment_code'` on field 'CharField' in serializer 'AppointmentListtSerializer', because it is the same as the field name. Remove the `source` keyword argument.")
\Traceback (most recent call last):
  File "/home/atifusman/Projects/patients_counsellor_appointments/patients_counsellor_appointments/appointmentsapp/views.py", line 575, in get
    response={'msg':'success','status':200,'total_pages':total_pages,'total_records':total_records,'current_page':page,'records':data_list.count(),'data':serializer.data}
  File "/home/atifusman/Projects/patients_counsellor_appointments/.venv/lib/python3.9/site-packages/rest_framework/serializers.py", line 745, in data
    ret = super().data
  File "/home/atifusman/Projects/patients_counsellor_appointments/.venv/lib/python3.9/site-packages/rest_framework/serializers.py", line 246, in data
    self._data = self.to_representation(self.instance)
  File "/home/atifusman/Projects/patients_counsellor_appointments/.venv/lib/python3.9/site-packages/rest_framework/serializers.py", line 663, in to_representation
    return [
  File "/home/atifusman/Projects/patients_counsellor_appointments/.venv/lib/python3.9/site-packages/rest_framework/serializers.py", line 664, in <listcomp>
    self.child.to_representation(item) for item in iterable
  File "/home/atifusman/Projects/patients_counsellor_appointments/.venv/lib/python3.9/site-packages/rest_framework/serializers.py", line 500, in to_representation
    for field in fields:
  File "/home/atifusman/Projects/patients_counsellor_appointments/.venv/lib/python3.9/site-packages/rest_framework/serializers.py", line 361, in _readable_fields
    for field in self.fields.values():
  File "/home/atifusman/Projects/patients_counsellor_appointments/.venv/lib/python3.9/site-packages/django/utils/functional.py", line 48, in __get__
    res = instance.__dict__[self.name] = self.func(instance)
  File "/home/atifusman/Projects/patients_counsellor_appointments/.venv/lib/python3.9/site-packages/rest_framework/serializers.py", line 350, in fields
    fields[key] = value
  File "/home/atifusman/Projects/patients_counsellor_appointments/.venv/lib/python3.9/site-packages/rest_framework/utils/serializer_helpers.py", line 152, in __setitem__
    field.bind(field_name=key, parent=self.serializer)
  File "/home/atifusman/Projects/patients_counsellor_appointments/.venv/lib/python3.9/site-packages/rest_framework/fields.py", line 378, in bind
    assert self.source != field_name, (
AssertionError: It is redundant to specify `source='appointment_code'` on field 'CharField' in serializer 'AppointmentListtSerializer', because it is the same as the field name. Remove the `source` keyword argument.

Cuurent Inputs:<QueryDict: {'patient_id': ['1'], 'appointment_date': ['2023-11-29']}>
Error Date/Time:2023-10-25 17:42:57
URL:http://localhost:8000/appointments/api/active-appointment-list/
Error:AssertionError("It is redundant to specify `source='appointment_code'` on field 'CharField' in serializer 'AppointmentListtSerializer', because it is the same as the field name. Remove the `source` keyword argument.")
\Traceback (most recent call last):
  File "/home/atifusman/Projects/patients_counsellor_appointments/patients_counsellor_appointments/appointmentsapp/views.py", line 575, in get
    response={'msg':'success','status':200,'total_pages':total_pages,'total_records':total_records,'current_page':page,'records':data_list.count(),'data':serializer.data}
  File "/home/atifusman/Projects/patients_counsellor_appointments/.venv/lib/python3.9/site-packages/rest_framework/serializers.py", line 745, in data
    ret = super().data
  File "/home/atifusman/Projects/patients_counsellor_appointments/.venv/lib/python3.9/site-packages/rest_framework/serializers.py", line 246, in data
    self._data = self.to_representation(self.instance)
  File "/home/atifusman/Projects/patients_counsellor_appointments/.venv/lib/python3.9/site-packages/rest_framework/serializers.py", line 663, in to_representation
    return [
  File "/home/atifusman/Projects/patients_counsellor_appointments/.venv/lib/python3.9/site-packages/rest_framework/serializers.py", line 664, in <listcomp>
    self.child.to_representation(item) for item in iterable
  File "/home/atifusman/Projects/patients_counsellor_appointments/.venv/lib/python3.9/site-packages/rest_framework/serializers.py", line 500, in to_representation
    for field in fields:
  File "/home/atifusman/Projects/patients_counsellor_appointments/.venv/lib/python3.9/site-packages/rest_framework/serializers.py", line 361, in _readable_fields
    for field in self.fields.values():
  File "/home/atifusman/Projects/patients_counsellor_appointments/.venv/lib/python3.9/site-packages/django/utils/functional.py", line 48, in __get__
    res = instance.__dict__[self.name] = self.func(instance)
  File "/home/atifusman/Projects/patients_counsellor_appointments/.venv/lib/python3.9/site-packages/rest_framework/serializers.py", line 350, in fields
    fields[key] = value
  File "/home/atifusman/Projects/patients_counsellor_appointments/.venv/lib/python3.9/site-packages/rest_framework/utils/serializer_helpers.py", line 152, in __setitem__
    field.bind(field_name=key, parent=self.serializer)
  File "/home/atifusman/Projects/patients_counsellor_appointments/.venv/lib/python3.9/site-packages/rest_framework/fields.py", line 378, in bind
    assert self.source != field_name, (
AssertionError: It is redundant to specify `source='appointment_code'` on field 'CharField' in serializer 'AppointmentListtSerializer', because it is the same as the field name. Remove the `source` keyword argument.

Cuurent Inputs:<QueryDict: {'patient_id': ['1'], 'appointment_date': ['2023-11-29']}>
Error Date/Time:2023-10-25 17:55:17
URL:http://localhost:8000/appointments/api/active-appointment-daterange/
Error:NameError("name 'start_date_date' is not defined")
\Traceback (most recent call last):
  File "/home/atifusman/Projects/patients_counsellor_appointments/patients_counsellor_appointments/appointmentsapp/views.py", line 610, in get
    search_start_date=start_date_date
NameError: name 'start_date_date' is not defined

Cuurent Inputs:<QueryDict: {'start_date': ['2023-10-01'], 'end_date': ['2023-10-31']}>
Error Date/Time:2023-10-25 18:44:50
URL:http://localhost:8000/appointments/api/appointment-delete/
Error:NameError("name 'queryset' is not defined")
\Traceback (most recent call last):
  File "/home/atifusman/Projects/patients_counsellor_appointments/patients_counsellor_appointments/appointmentsapp/views.py", line 619, in post
    total_records=queryset.count()
NameError: name 'queryset' is not defined

Cuurent Inputs:<QueryDict: {'start_date': ['2023-10-01'], 'end_date': ['2023-11-30']}>
Error Date/Time:2023-10-25 18:45:48
URL:http://localhost:8000/appointments/api/appointment-delete/
Error:NameError("name 'queryset' is not defined")
\Traceback (most recent call last):
  File "/home/atifusman/Projects/patients_counsellor_appointments/patients_counsellor_appointments/appointmentsapp/views.py", line 619, in post
    total_records=queryset.count()
NameError: name 'queryset' is not defined

Cuurent Inputs:<QueryDict: {'start_date': ['2023-10-01'], 'end_date': ['2023-11-30']}>
Error Date/Time:2023-10-25 18:49:49
URL:http://localhost:8000/appointments/api/appointment-delete/
Error:NameError("name 'queryset' is not defined")
\Traceback (most recent call last):
  File "/home/atifusman/Projects/patients_counsellor_appointments/patients_counsellor_appointments/appointmentsapp/views.py", line 616, in post
    total_records=queryset.count()
NameError: name 'queryset' is not defined

Cuurent Inputs:<QueryDict: {'start_date': ['2023-10-01'], 'end_date': ['2023-11-30']}>